Workbook
Name NS_BAR_V3_V1: #REF!
Name CT_MASM_V3: #REF!
Name NS_TM10_V5_V1: #REF!
Name NS_EQ_V4: #REF!
Name NS_mGES_V4: #REF!
Name CT_EQ_V5: #REF!
Name CT_BAR_V5: #REF!
Name CT_MASw_V4_V1: #REF!
Name NS_MRC5_V2_V1: #REF!
Name NS_TM10_V2: #REF!
Name NS_BAR_V1: #REF!
Name NS_TM6_V2: #REF!
Name NS_MAS2_V5: #REF!
Name NS_MAS0_V5: #REF!
Name NS_MRC5_V2: #REF!
Name NS_TM6_V1: 'Groupe NS'!$L$4:$L$1000
Name CT_FAC_V4_V1: 'Groupe controle'!$H$4:$H$999
Name CT_MRC3_V5: #REF!
Name CT_MAS0_V4_V1: #REF!
Name CT_MAS2_V5_V1: #REF!
Name CT_TM6_V1: 'Groupe controle'!$L$4:$L$999
Name CT_EQ_V4_V1: #REF!
Name NS_MRC_V5: #REF!
Name NS_MRCw_V3_V1: #REF!
Name CT_EQ_V4: #REF!
Name CT_mGES_V4_V1: #REF!
Name CT_MRC3_V5_V1: #REF!
Name CT_MAS_V2_V1: #REF!
Name NS_MAS2_V2_V1: #REF!
Name NS_MRC_V4_V1: 'Groupe NS'!$W$4:$W$1000
Name NS_MRC_V3: #REF!
Name CT_TM6_V2_V1: #REF!
Name NS_MRC3_V5_V1: #REF!
Name CT_MAS0_V4: #REF!
Name CT_MAS_V4_V1: 'Groupe controle'!$T$4:$T$999
Name NS_MASi_V2_V1: #REF!
Name NS_MAS_V3_V1: #REF!
Name NS_TM10_V3_V1: #REF!
Name CT_MRC3_V4_V1: #REF!
Name CT_BAR_V3_V1: #REF!
Name NS_MASM_V5_V1: #REF!
Name NS_MRC3_V2: #REF!
Name NS_TUG_V5: #REF!
Name NS_MASw_V5_V1: #REF!
Name NS_FAC_V5: #REF!
Name CT_MRCm_V1: #REF!
Name NS_TUG_V3: #REF!
Name CT_MAS2_V5: #REF!
Name NS_BAR_V5_V1: #REF!
Name CT_TM6_V5_V1: #REF!
Name CT_MRC3_V1: #REF!
Name NS_TUG_V5_V1: #REF!
Name CT_FAC_V2_V1: #REF!
Name NS_TUG_V2: #REF!
Name CT_TM10_V2: #REF!
Name NS_FAC_V5_V1: #REF!
Name NS_TM10_V3: #REF!
Name NS_TM6_V5_V1: #REF!
Name NS_MRC3_V4_V1: #REF!
Name CT_MASM_V3_V1: #REF!

Sheet Overview
A1: N total | B1: =countif(Data!C:C,1) -> 14 | C1: =B1/20 -> 0.7
A2: Neuroskin | B2: =COUNTIFS(Data!C:C,1,Data!H:H,0) -> 7
A3: Contrôle | B3: =COUNTIFS(Data!C:C,1,Data!H:H,1) -> 7
A5: Endpoint | B5: Δ | C5: Cliniquement significatif ? | E5: Statistiquement significatif
A6: Vitesse (10 m) | B6: =Stats!P5 -> 0.17199729 | C6: 0.16 m/s | D6: Oui (1xMCID) | E6: =IF(LEFT(Stats!W5,2)="No","Non","Oui") -> Non
A7: Distance (6 min) | B7: =Stats!P11 -> 8.3714286 | C7: 34.4 m | D7: Non (MCID) | E7: =IF(LEFT(Stats!W11,2)="No","Non","Oui") -> Non
A8: Équilibre - risque de chute (TUG) | B8: =Stats!P17 -> -9.0685714 | C8: 2.9 s | D8: Oui (3xMDC) | E8: =IF(LEFT(Stats!W17,2)="No","Non","Oui") -> Non
A9: Capacité de marche (NFAC) | B9: =Stats!AL24 -> 1.0571429 | C9: 1 | D9: Oui (Ordinal) | E9: =IF(LEFT(Stats!AN24,2)="No","Non","Oui") -> Non
A10: Spasticité (MAS total) | B10: =Stats!V32 -> -1 | C10: 0.45 to 0.73 | D10: Oui (2xMCID average) | E10: =IF(LEFT(Stats!X32,2)="No","Non","Oui") -> Non
A11: Force (MRC total) | B11: =Stats!X77 -> 0.6 | C11: - | D11: - | E11: =IF(LEFT(Stats!Z77,2)="No","Non","Oui") -> Non

Sheet Stats
A1: 10MWT | B1: NS | I1: CONTROL | P1: NS versus CONTROL
A2: Visit | B2: Named range | C2: N | D2: Mean | E2: SD | F2: Median | G2: Min | H2: Max | I2: Named range | J2: N | K2: Mean | L2: SD | M2: Median | N2: Min | O2: Max | P2: Δ | Q2: p-value | R2: std error | S2: Welch DF | T2: 95% CI lower | U2: 95% CI upper | V2: 95% CI | W2: Significance
A3: V1 | B3: NS_TM10_V1 | C3: =IFERROR(__xludf.DUMMYFUNCTION("SUMPRODUCT(--REGEXMATCH(TO_TEXT(INDIRECT(B3)), ""^\s*-?\d+(\.\d+)?\s*$""))"),7.0) -> 7 | D3: =AVERAGE(INDIRECT(B3)) -> 0.42108245 | E3: =STDEV(INDIRECT(B3)) -> 0.18525867 | F3: =MEDIAN(INDIRECT(B3)) -> 0.38461538 | G3: =MIN(INDIRECT(B3)) -> 0.21276596 | H3: =MAX(INDIRECT(B3)) -> 0.76335878 | I3: CT_TM10_V1 | J3: =IFERROR(__xludf.DUMMYFUNCTION("SUMPRODUCT(--REGEXMATCH(TO_TEXT(INDIRECT(I3)), ""^\s*-?\d+(\.\d+)?\s*$""))"),5.0) -> 5 | K3: =AVERAGE(INDIRECT(I3)) -> 0.56391638 | L3: =STDEV(INDIRECT(I3)) -> 0.25227198 | M3: =MEDIAN(INDIRECT(I3)) -> 0.60240964 | N3: =MIN(INDIRECT(I3)) -> 0.25641026 | O3: =MAX(INDIRECT(I3)) -> 0.92592593 | P3: - | Q3: - | W3: -
A4: V4 | B4: NS_TM10_V4 | C4: =IFERROR(__xludf.DUMMYFUNCTION("SUMPRODUCT(--REGEXMATCH(TO_TEXT(INDIRECT(B4)), ""^\s*-?\d+(\.\d+)?\s*$""))"),7.0) -> 7 | D4: =AVERAGE(INDIRECT(B4)) -> 0.88976942 | E4: =STDEV(INDIRECT(B4)) -> 0.37470217 | F4: =MEDIAN(INDIRECT(B4)) -> 0.83333333 | G4: =MIN(INDIRECT(B4)) -> 0.48076923 | H4: =MAX(INDIRECT(B4)) -> 1.4285714 | I4: CT_TM10_V4 | J4: =IFERROR(__xludf.DUMMYFUNCTION("SUMPRODUCT(--REGEXMATCH(TO_TEXT(INDIRECT(I4)), ""^\s*-?\d+(\.\d+)?\s*$""))"),5.0) -> 5 | K4: =AVERAGE(INDIRECT(I4)) -> 0.86060606 | L4: =STDEV(INDIRECT(I4)) -> 0.27013357 | M4: =MEDIAN(INDIRECT(I4)) -> 0.90909091 | N4: =MIN(INDIRECT(I4)) -> 0.50505051 | O4: =MAX(INDIRECT(I4)) -> 1.1111111 | P4: - | Q4: - | W4: -
A5: V4-V1 | B5: NS_TM10_V4_V1 | C5: =IFERROR(__xludf.DUMMYFUNCTION("SUMPRODUCT(--REGEXMATCH(TO_TEXT(INDIRECT(B5)), ""^\s*-?\d+(\.\d+)?\s*$""))"),7.0) -> 7 | D5: =AVERAGE(INDIRECT(B5)) -> 0.46868697 | E5: =STDEV(INDIRECT(B5)) -> 0.28886747 | F5: =MEDIAN(INDIRECT(B5)) -> 0.44871795 | G5: =MIN(INDIRECT(B5)) -> 0.13888889 | H5: =MAX(INDIRECT(B5)) -> 0.88734405 | I5: CT_TM10_V4_V1 | J5: =IFERROR(__xludf.DUMMYFUNCTION("SUMPRODUCT(--REGEXMATCH(TO_TEXT(INDIRECT(I5)), ""^\s*-?\d+(\.\d+)?\s*$""))"),5.0) -> 5 | K5: =AVERAGE(INDIRECT(I5)) -> 0.29668968 | L5: =STDEV(INDIRECT(I5)) -> 0.37424999 | M5: =MEDIAN(INDIRECT(I5)) -> 0.095214439 | N5: =MIN(INDIRECT(I5)) -> -0.016835017 | O5: =MAX(INDIRECT(I5)) -> 0.85470085 | P5: =D5-K5 -> 0.17199729 | Q5: =IFERROR(__xludf.DUMMYFUNCTION("T.TEST( FILTER(INDIRECT(B5), ISNUMBER(INDIRECT(B5))), FILTER(INDIRECT(I5), ISNUMBER(INDIRECT(I5))), 2, 3 )"),0.4169423983469147) -> 0.4169424 | R5: =IF(AND(C5>=2,J5>=2,ISNUMBER(E5),ISNUMBER(L5)),SQRT(E5^2/C5+L5^2/J5),"") -> 0.19983303 | S5: =IF(AND(C5>=2,J5>=2,R5<>"",E5>0,L5>0),((E5^2/C5+L5^2/J5)^2)/(((E5^2/C5)^2)/(C5-1)+((L5^2/J5)^2)/(J5-1)),"") -> 7.253082 | T5: =IF(AND(ISNUMBER(P5),ISNUMBER(R5),ISNUMBER(S5)),P5-_xlfn.T.INV.2T(0.05,S5)*R5,"") -> -0.30053275 | U5: =IF(AND(ISNUMBER(P5),ISNUMBER(R5),ISNUMBER(S5)),P5+_xlfn.T.INV.2T(0.05,S5)*R5,"") -> 0.64452733 | V5: =IF(AND(ISNUMBER(T5),ISNUMBER(U5)),"["&TEXT(T5,"0.000")&"; "&TEXT(U5,"0.000")&"]","") -> [-0.301; 0.645] | W5: =IFS( OR(NOT(ISNUMBER(Q5)),NOT(ISNUMBER(T5)),NOT(ISNUMBER(U5))),"", OR(Q5<0,Q5>1),"Invalid p-value", T5>U5,"Invalid CI", AND(Q5<0.05,T5>0,U5>0),"Statistically significant - positive difference", AND(Q5<0.05,T5<0,U5<0),"Statistically significant - negative difference", AND(Q5>=0.05,T5<=0,U5>=0),"Not statistically significant", AND(Q5<0.05,T5<=0,U5>=0),"Inconsistent: p < 0.05 but CI includes 0", AND(Q5>=0.05,OR(AND(T5>0,U5>0),AND(T5<0,U5<0))),"Inconsistent: p ≥ 0.05 but CI excludes 0", TRUE,"Check values" ) -> Not statistically significant
A7: 6MWT | B7: NS | I7: CONTROL | P7: NS versus CONTROL
A8: Visit | B8: Named range | C8: N | D8: Mean | E8: SD | F8: Median | G8: Min | H8: Max | I8: Named range | J8: N | K8: Mean | L8: SD | M8: Median | N8: Min | O8: Max | P8: Δ | Q8: p-value | R8: std error | S8: Welch DF | T8: 95% CI lower | U8: 95% CI upper | V8: 95% CI | W8: Significance
A9: V1 | B9: NS_TM6_V1 | C9: =IFERROR(__xludf.DUMMYFUNCTION("SUMPRODUCT(--REGEXMATCH(TO_TEXT(INDIRECT(B9)), ""^\s*-?\d+(\.\d+)?\s*$""))"),7.0) -> 7 | D9: =AVERAGE(INDIRECT(B9)) -> 153.28571 | E9: =STDEV(INDIRECT(B9)) -> 86.634701 | F9: =MEDIAN(INDIRECT(B9)) -> 147 | G9: =MIN(INDIRECT(B9)) -> 36 | H9: =MAX(INDIRECT(B9)) -> 274 | I9: CT_TM6_V1 | J9: =IFERROR(__xludf.DUMMYFUNCTION("SUMPRODUCT(--REGEXMATCH(TO_TEXT(INDIRECT(I9)), ""^\s*-?\d+(\.\d+)?\s*$""))"),5.0) -> 5 | K9: =AVERAGE(INDIRECT(I9)) -> 130.4 | L9: =STDEV(INDIRECT(I9)) -> 49.064244 | M9: =MEDIAN(INDIRECT(I9)) -> 108 | N9: =MIN(INDIRECT(I9)) -> 77 | O9: =MAX(INDIRECT(I9)) -> 187 | P9: - | Q9: - | W9: -
A10: V4 | B10: NS_TM6_V4 | C10: =IFERROR(__xludf.DUMMYFUNCTION("SUMPRODUCT(--REGEXMATCH(TO_TEXT(INDIRECT(B10)), ""^\s*-?\d+(\.\d+)?\s*$""))"),7.0) -> 7 | D10: =AVERAGE(INDIRECT(B10)) -> 286.85714 | E10: =STDEV(INDIRECT(B10)) -> 121.64077 | F10: =MEDIAN(INDIRECT(B10)) -> 285 | G10: =MIN(INDIRECT(B10)) -> 128 | H10: =MAX(INDIRECT(B10)) -> 429 | I10: CT_TM6_V4 | J10: =IFERROR(__xludf.DUMMYFUNCTION("SUMPRODUCT(--REGEXMATCH(TO_TEXT(INDIRECT(I10)), ""^\s*-?\d+(\.\d+)?\s*$""))"),5.0) -> 5 | K10: =AVERAGE(INDIRECT(I10)) -> 255.6 | L10: =STDEV(INDIRECT(I10)) -> 132.72076 | M10: =MEDIAN(INDIRECT(I10)) -> 228 | N10: =MIN(INDIRECT(I10)) -> 126 | O10: =MAX(INDIRECT(I10)) -> 480 | P10: - | Q10: - | W10: -
A11: V4-V1 | B11: NS_TM6_V4_V1 | C11: =IFERROR(__xludf.DUMMYFUNCTION("SUMPRODUCT(--REGEXMATCH(TO_TEXT(INDIRECT(B11)), ""^\s*-?\d+(\.\d+)?\s*$""))"),7.0) -> 7 | D11: =AVERAGE(INDIRECT(B11)) -> 133.57143 | E11: =STDEV(INDIRECT(B11)) -> 98.149303 | F11: =MEDIAN(INDIRECT(B11)) -> 117 | G11: =MIN(INDIRECT(B11)) -> 33 | H11: =MAX(INDIRECT(B11)) -> 317 | I11: CT_TM6_V4_V1 | J11: =IFERROR(__xludf.DUMMYFUNCTION("SUMPRODUCT(--REGEXMATCH(TO_TEXT(INDIRECT(I11)), ""^\s*-?\d+(\.\d+)?\s*$""))"),5.0) -> 5 | K11: =AVERAGE(INDIRECT(I11)) -> 125.2 | L11: =STDEV(INDIRECT(I11)) -> 108.98486 | M11: =MEDIAN(INDIRECT(I11)) -> 126 | N11: =MIN(INDIRECT(I11)) -> 23 | O11: =MAX(INDIRECT(I11)) -> 302 | P11: =D11-K11 -> 8.3714286 | Q11: =IFERROR(__xludf.DUMMYFUNCTION("T.TEST( FILTER(INDIRECT(B11), ISNUMBER(INDIRECT(B11))), FILTER(INDIRECT(I11), ISNUMBER(INDIRECT(I11))), 2, 3 )"),0.8946037886057816) -> 0.89460379 | R11: =IF(AND(C11>=2,J11>=2,ISNUMBER(E11),ISNUMBER(L11)),SQRT(E11^2/C11+L11^2/J11),"") -> 61.251316 | S11: =IF(AND(C11>=2,J11>=2,R11<>"",E11>0,L11>0),((E11^2/C11+L11^2/J11)^2)/(((E11^2/C11)^2)/(C11-1)+((L11^2/J11)^2)/(J11-1)),"") -> 8.1528428 | T11: =IF(AND(ISNUMBER(P11),ISNUMBER(R11),ISNUMBER(S11)),P11-_xlfn.T.INV.2T(0.05,S11)*R11,"") -> -132.87436 | U11: =IF(AND(ISNUMBER(P11),ISNUMBER(R11),ISNUMBER(S11)),P11+_xlfn.T.INV.2T(0.05,S11)*R11,"") -> 149.61722 | V11: =IF(AND(ISNUMBER(T11),ISNUMBER(U11)),"["&TEXT(T11,"0.000")&"; "&TEXT(U11,"0.000")&"]","") -> [-132.874; 149.617] | W11: =IFS( OR(NOT(ISNUMBER(Q11)),NOT(ISNUMBER(T11)),NOT(ISNUMBER(U11))),"", OR(Q11<0,Q11>1),"Invalid p-value", T11>U11,"Invalid CI", AND(Q11<0.05,T11>0,U11>0),"Statistically significant - positive difference", AND(Q11<0.05,T11<0,U11<0),"Statistically significant - negative difference", AND(Q11>=0.05,T11<=0,U11>=0),"Not statistically significant", AND(Q11<0.05,T11<=0,U11>=0),"Inconsistent: p < 0.05 but CI includes 0", AND(Q11>=0.05,OR(AND(T11>0,U11>0),AND(T11<0,U11<0))),"Inconsistent: p ≥ 0.05 but CI excludes 0", TRUE,"Check values" ) -> Not statistically significant
A13: TUG | B13: NS | I13: CONTROL | P13: NS versus CONTROL
A14: Visit | B14: Named range | C14: N | D14: Mean | E14: SD | F14: Median | G14: Min | H14: Max | I14: Named range | J14: N | K14: Mean | L14: SD | M14: Median | N14: Min | O14: Max | P14: Δ | Q14: p-value | R14: std error | S14: Welch DF | T14: 95% CI lower | U14: 95% CI upper | V14: 95% CI | W14: Significance
A15: V1 | B15: NS_TUG_V1 | C15: =IFERROR(__xludf.DUMMYFUNCTION("SUMPRODUCT(--REGEXMATCH(TO_TEXT(INDIRECT(B15)), ""^\s*-?\d+(\.\d+)?\s*$""))"),7.0) -> 7 | D15: =AVERAGE(INDIRECT(B15)) -> 32.6 | E15: =STDEV(INDIRECT(B15)) -> 28.85452 | F15: =MEDIAN(INDIRECT(B15)) -> 19 | G15: =MIN(INDIRECT(B15)) -> 13.7 | H15: =MAX(INDIRECT(B15)) -> 95 | I15: CT_TUG_V1 | J15: =IFERROR(__xludf.DUMMYFUNCTION("SUMPRODUCT(--REGEXMATCH(TO_TEXT(INDIRECT(I15)), ""^\s*-?\d+(\.\d+)?\s*$""))"),5.0) -> 5 | K15: =AVERAGE(INDIRECT(I15)) -> 21.3 | L15: =STDEV(INDIRECT(I15)) -> 8.1363382 | M15: =MEDIAN(INDIRECT(I15)) -> 20 | N15: =MIN(INDIRECT(I15)) -> 11.5 | O15: =MAX(INDIRECT(I15)) -> 31 | P15: - | Q15: - | W15: -
A16: V4 | B16: NS_TUG_V4 | C16: =IFERROR(__xludf.DUMMYFUNCTION("SUMPRODUCT(--REGEXMATCH(TO_TEXT(INDIRECT(B16)), ""^\s*-?\d+(\.\d+)?\s*$""))"),7.0) -> 7 | D16: =AVERAGE(INDIRECT(B16)) -> 13.751429 | E16: =STDEV(INDIRECT(B16)) -> 9.4823264 | F16: =MEDIAN(INDIRECT(B16)) -> 9 | G16: =MIN(INDIRECT(B16)) -> 5.8 | H16: =MAX(INDIRECT(B16)) -> 30.1 | I16: CT_TUG_V4 | J16: =IFERROR(__xludf.DUMMYFUNCTION("SUMPRODUCT(--REGEXMATCH(TO_TEXT(INDIRECT(I16)), ""^\s*-?\d+(\.\d+)?\s*$""))"),5.0) -> 5 | K16: =AVERAGE(INDIRECT(I16)) -> 11.52 | L16: =STDEV(INDIRECT(I16)) -> 3.5513378 | M16: =MEDIAN(INDIRECT(I16)) -> 11 | N16: =MIN(INDIRECT(I16)) -> 7.2 | O16: =MAX(INDIRECT(I16)) -> 17 | P16: - | Q16: - | W16: -
A17: V4-V1 | B17: NS_TUG_V4_V1 | C17: =IFERROR(__xludf.DUMMYFUNCTION("SUMPRODUCT(--REGEXMATCH(TO_TEXT(INDIRECT(B17)), ""^\s*-?\d+(\.\d+)?\s*$""))"),7.0) -> 7 | D17: =AVERAGE(INDIRECT(B17)) -> -18.848571 | E17: =STDEV(INDIRECT(B17)) -> 22.21037 | F17: =MEDIAN(INDIRECT(B17)) -> -9.3 | G17: =MIN(INDIRECT(B17)) -> -64.9 | H17: =MAX(INDIRECT(B17)) -> -3.7 | I17: CT_TUG_V4_V1 | J17: =IFERROR(__xludf.DUMMYFUNCTION("SUMPRODUCT(--REGEXMATCH(TO_TEXT(INDIRECT(I17)), ""^\s*-?\d+(\.\d+)?\s*$""))"),5.0) -> 5 | K17: =AVERAGE(INDIRECT(I17)) -> -9.78 | L17: =STDEV(INDIRECT(I17)) -> 6.3915569 | M17: =MEDIAN(INDIRECT(I17)) -> -9 | N17: =MIN(INDIRECT(I17)) -> -19 | O17: =MAX(INDIRECT(I17)) -> -1.1 | P17: =D17-K17 -> -9.0685714 | Q17: =IFERROR(__xludf.DUMMYFUNCTION("T.TEST( FILTER(INDIRECT(B17), ISNUMBER(INDIRECT(B17))), FILTER(INDIRECT(I17), ISNUMBER(INDIRECT(I17))), 2, 3 )"),0.33907422531666975) -> 0.33907423 | R17: =IF(AND(C17>=2,J17>=2,ISNUMBER(E17),ISNUMBER(L17)),SQRT(E17^2/C17+L17^2/J17),"") -> 8.868027 | S17: =IF(AND(C17>=2,J17>=2,R17<>"",E17>0,L17>0),((E17^2/C17+L17^2/J17)^2)/(((E17^2/C17)^2)/(C17-1)+((L17^2/J17)^2)/(J17-1)),"") -> 7.3242427 | T17: =IF(AND(ISNUMBER(P17),ISNUMBER(R17),ISNUMBER(S17)),P17-_xlfn.T.INV.2T(0.05,S17)*R17,"") -> -30.038123 | U17: =IF(AND(ISNUMBER(P17),ISNUMBER(R17),ISNUMBER(S17)),P17+_xlfn.T.INV.2T(0.05,S17)*R17,"") -> 11.90098 | V17: =IF(AND(ISNUMBER(T17),ISNUMBER(U17)),"["&TEXT(T17,"0.000")&"; "&TEXT(U17,"0.000")&"]","") -> [-30.038; 11.901] | W17: =IFS( OR(NOT(ISNUMBER(Q17)),NOT(ISNUMBER(T17)),NOT(ISNUMBER(U17))),"", OR(Q17<0,Q17>1),"Invalid p-value", T17>U17,"Invalid CI", AND(Q17<0.05,T17>0,U17>0),"Statistically significant - positive difference", AND(Q17<0.05,T17<0,U17<0),"Statistically significant - negative difference", AND(Q17>=0.05,T17<=0,U17>=0),"Not statistically significant", AND(Q17<0.05,T17<=0,U17>=0),"Inconsistent: p < 0.05 but CI includes 0", AND(Q17>=0.05,OR(AND(T17>0,U17>0),AND(T17<0,U17<0))),"Inconsistent: p ≥ 0.05 but CI excludes 0", TRUE,"Check values" ) -> Not statistically significant
A20: NFAC | B20: NS | T20: CONTROL | AL20: NS versus CONTROL
A21: Visit | B21: Named range | C21: N | D21: Mean | E21: SD | F21: Median | G21: Min | H21: Max | I21: Headroom | J21: % at max | K21: % ≥ 4 | L21: Median % of ➚ HR | M21: Median ΔNFAC [Q1-Q3] | N21: Mean ΔNFAC ± SD | O21: % improved | P21: % stable | Q21: % worsened | R21: % reaching ≥4 | S21: % reaching 8 | T21: Named range | U21: N | V21: Mean | W21: SD | X21: Median | Y21: Min | Z21: Max | AA21: Headroom | AB21: % at max | AC21: % ≥ 4 | AD21: Median % of ➚ HR | AE21: Median ΔNFAC [Q1-Q3] | AF21: Mean ΔNFAC ± SD | AG21: % improved | AH21: % stable | AI21: % worsened | AJ21: % reaching ≥4 | AK21: % reaching 8 | AL21: Δ | AM21: p-value | AN21: Significance
A22: V1 | B22: NS_FAC_V1 | C22: =IFERROR(__xludf.DUMMYFUNCTION("SUMPRODUCT(--REGEXMATCH(TO_TEXT(INDIRECT(B22)), ""^\s*-?\d+(\.\d+)?\s*$""))"),7.0) -> 7 | D22: =AVERAGE(INDIRECT(B22)) -> 3.7142857 | E22: =STDEV(INDIRECT(B22)) -> 0.95118973 | F22: =MEDIAN(INDIRECT(B22)) -> 3 | G22: =MIN(INDIRECT(B22)) -> 3 | H22: =MAX(INDIRECT(B22)) -> 5 | I22: =IFERROR(__xludf.DUMMYFUNCTION("IFERROR( LET( r, FILTER(INDIRECT(B22), ISNUMBER(INDIRECT(B22))), 8-AVERAGE(r) ), """" )"),4.285714285714286) -> 4.2857143 | J22: =IFERROR(__xludf.DUMMYFUNCTION("IFERROR( LET( r, FILTER(INDIRECT(B22), ISNUMBER(INDIRECT(B22))), atmax, COUNTIF(r, 8), total, COUNT(r), atmax&""/""&total&"" (""&TEXT(atmax/total, ""0%"")&"")"" ), """" )"),"0/7 (0%)") -> 0/7 (0%) | K22: =IFERROR(__xludf.DUMMYFUNCTION("IFERROR( LET( r, FILTER(INDIRECT(B22), ISNUMBER(INDIRECT(B22))), independent, COUNTIF(r, "">=4""), total, COUNT(r), independent&""/""&total&"" (""&TEXT(independent/total, ""0%"")&"")"" ), """" )"),"3/7 (43%)") -> 3/7 (43%) | O22: - | P22: - | Q22: - | R22: - | S22: - | T22: CT_FAC_V1 | U22: =IFERROR(__xludf.DUMMYFUNCTION("SUMPRODUCT(--REGEXMATCH(TO_TEXT(INDIRECT(T22)), ""^\s*-?\d+(\.\d+)?\s*$""))"),5.0) -> 5 | V22: =AVERAGE(INDIRECT(T22)) -> 2.8 | W22: =STDEV(INDIRECT(T22)) -> 0.83666003 | X22: =MEDIAN(INDIRECT(T22)) -> 3 | Y22: =MIN(INDIRECT(T22)) -> 2 | Z22: =MAX(INDIRECT(T22)) -> 4 | AA22: =IFERROR(__xludf.DUMMYFUNCTION("IFERROR( LET( r, FILTER(INDIRECT(T22), ISNUMBER(INDIRECT(T22))), 8-AVERAGE(r) ), """" )"),5.2) -> 5.2 | AB22: =IFERROR(__xludf.DUMMYFUNCTION("IFERROR( LET( r, FILTER(INDIRECT(T22), ISNUMBER(INDIRECT(T22))), atmax, COUNTIF(r, 8), total, COUNT(r), atmax&""/""&total&"" (""&TEXT(atmax/total, ""0%"")&"")"" ), """" )"),"0/5 (0%)") -> 0/5 (0%) | AC22: =IFERROR(__xludf.DUMMYFUNCTION("IFERROR( LET( r, FILTER(INDIRECT(T22), ISNUMBER(INDIRECT(T22))), independent, COUNTIF(r, "">=4""), total, COUNT(r), independent&""/""&total&"" (""&TEXT(independent/total, ""0%"")&"")"" ), """" )"),"1/5 (20%)") -> 1/5 (20%) | AG22: - | AH22: - | AI22: - | AJ22: - | AL22: - | AM22: - | AN22: -
A23: V4 | B23: NS_FAC_V4 | C23: =IFERROR(__xludf.DUMMYFUNCTION("SUMPRODUCT(--REGEXMATCH(TO_TEXT(INDIRECT(B23)), ""^\s*-?\d+(\.\d+)?\s*$""))"),7.0) -> 7 | D23: =AVERAGE(INDIRECT(B23)) -> 6.5714286 | E23: =STDEV(INDIRECT(B23)) -> 1.3972763 | F23: =MEDIAN(INDIRECT(B23)) -> 7 | G23: =MIN(INDIRECT(B23)) -> 4 | H23: =MAX(INDIRECT(B23)) -> 8 | I23: =IFERROR(__xludf.DUMMYFUNCTION("IFERROR( LET( r, FILTER(INDIRECT(B23), ISNUMBER(INDIRECT(B23))), 8-AVERAGE(r) ), """" )"),1.4285714285714288) -> 1.4285714 | J23: =IFERROR(__xludf.DUMMYFUNCTION("IFERROR( LET( r, FILTER(INDIRECT(B23), ISNUMBER(INDIRECT(B23))), atmax, COUNTIF(r, 8), total, COUNT(r), atmax&""/""&total&"" (""&TEXT(atmax/total, ""0%"")&"")"" ), """" )"),"2/7 (29%)") -> 2/7 (29%) | K23: =IFERROR(__xludf.DUMMYFUNCTION("IFERROR( LET( r, FILTER(INDIRECT(B23), ISNUMBER(INDIRECT(B23))), independent, COUNTIF(r, "">=4""), total, COUNT(r), independent&""/""&total&"" (""&TEXT(independent/total, ""0%"")&"")"" ), """" )"),"7/7 (100%)") -> 7/7 (100%) | O23: - | P23: - | Q23: - | R23: - | S23: - | T23: CT_FAC_V4 | U23: =IFERROR(__xludf.DUMMYFUNCTION("SUMPRODUCT(--REGEXMATCH(TO_TEXT(INDIRECT(T23)), ""^\s*-?\d+(\.\d+)?\s*$""))"),5.0) -> 5 | V23: =AVERAGE(INDIRECT(T23)) -> 4.6 | W23: =STDEV(INDIRECT(T23)) -> 0.89442719 | X23: =MEDIAN(INDIRECT(T23)) -> 5 | Y23: =MIN(INDIRECT(T23)) -> 3 | Z23: =MAX(INDIRECT(T23)) -> 5 | AA23: =IFERROR(__xludf.DUMMYFUNCTION("IFERROR( LET( r, FILTER(INDIRECT(T23), ISNUMBER(INDIRECT(T23))), 8-AVERAGE(r) ), """" )"),3.4000000000000004) -> 3.4 | AB23: =IFERROR(__xludf.DUMMYFUNCTION("IFERROR( LET( r, FILTER(INDIRECT(T23), ISNUMBER(INDIRECT(T23))), atmax, COUNTIF(r, 8), total, COUNT(r), atmax&""/""&total&"" (""&TEXT(atmax/total, ""0%"")&"")"" ), """" )"),"0/5 (0%)") -> 0/5 (0%) | AC23: =IFERROR(__xludf.DUMMYFUNCTION("IFERROR( LET( r, FILTER(INDIRECT(T23), ISNUMBER(INDIRECT(T23))), independent, COUNTIF(r, "">=4""), total, COUNT(r), independent&""/""&total&"" (""&TEXT(independent/total, ""0%"")&"")"" ), """" )"),"4/5 (80%)") -> 4/5 (80%) | AG23: - | AH23: - | AI23: - | AJ23: - | AL23: - | AM23: - | AN23: -
A24: V4-V1 | B24: NS_FAC_V4_V1 | C24: =IFERROR(__xludf.DUMMYFUNCTION("SUMPRODUCT(--REGEXMATCH(TO_TEXT(INDIRECT(B24)), ""^\s*-?\d+(\.\d+)?\s*$""))"),7.0) -> 7 | D24: =AVERAGE(INDIRECT(B24)) -> 2.8571429 | E24: =STDEV(INDIRECT(B24)) -> 1.069045 | F24: =MEDIAN(INDIRECT(B24)) -> 3 | G24: =MIN(INDIRECT(B24)) -> 1 | H24: =MAX(INDIRECT(B24)) -> 4 | I24: - | J24: - | K24: - | L24: =IFERROR(__xludf.DUMMYFUNCTION("IFERROR( LET( base, INDIRECT(B$22), follow, INDIRECT(B23), ratios, MAP(base, follow, LAMBDA(a, b, IF(AND(ISNUMBER(a), ISNUMBER(b), a<8), (b-a)/(8-a), """"))), clean, FILTER(ratios, ISNUMBER(ratios)), TEXT(MEDIAN(clean), ""0%"")&"" ["&"""&TEXT(QUARTILE(clean, 1), ""0%"")&""; ""&TEXT(QUARTILE(clean, 3), ""0%"")&""]"" ), """" )"),"80% [55%; 90%]") -> 80% [55%; 90%] | M24: =IFERROR(__xludf.DUMMYFUNCTION("IFERROR( LET( delta, FILTER(INDIRECT(B24), ISNUMBER(INDIRECT(B24))), TEXT(MEDIAN(delta), ""0"")&"" [""&TEXT(QUARTILE(delta, 1), ""0"")&""; ""&TEXT(QUARTILE(delta, 3), ""0"")&""]"" ), """" )"),"3 [3; 4]") -> 3 [3; 4] | N24: =IFERROR(__xludf.DUMMYFUNCTION("IFERROR( LET( delta, FILTER(INDIRECT(B24), ISNUMBER(INDIRECT(B24))), n, COUNT(delta), IF( n<2, TEXT(AVERAGE(delta), ""0.0""), TEXT(AVERAGE(delta), ""0.0"")&"" ± ""&TEXT(STDEV.S(delta), ""0.0"") ) ), """" )"),"2.9 ± 1.1") -> 2.9 ± 1.1 | O24: =IFERROR(__xludf.DUMMYFUNCTION("IFERROR( LET( r, INDIRECT(B24), improved, COUNTIF(r, "">0""), total, COUNT(FILTER(r, ISNUMBER(r))), improved&""/""&total&"" (""&TEXT(improved/total, ""0%"")&"")"" ), """" )"),"7/7 (100%)") -> 7/7 (100%) | P24: =IFERROR(__xludf.DUMMYFUNCTION("IFERROR( LET( r, INDIRECT(B24), stable, COUNTIF(r, 0), total, COUNT(FILTER(r, ISNUMBER(r))), stable&""/""&total&"" (""&TEXT(stable/total, ""0%"")&"")"" ), """" )"),"0/7 (0%)") -> 0/7 (0%) | Q24: =IFERROR(__xludf.DUMMYFUNCTION("IFERROR( LET( r, INDIRECT(B24), worsened, COUNTIF(r, ""<0""), total, COUNT(FILTER(r, ISNUMBER(r))), worsened&""/""&total&"" (""&TEXT(worsened/total, ""0%"")&"")"" ), """" )"),"0/7 (0%)") -> 0/7 (0%) | R24: {=IFERROR( LET( base, INDIRECT(B$22), follow, INDIRECT(B23), eligible, SUM(MAP(base, follow, LAMBDA(a, b, IF(AND(ISNUMBER(a), ISNUMBER(b), a<4), 1, 0)))), crossed, SUM(MAP(base, follow, LAMBDA(a, b, IF(AND(ISNUMBER(a), ISNUMBER(b), a<4, b>=4), 1, 0)))), crossed&"/"&eligible&" ("&TEXT(crossed/eligible, "0%")&")" ), "" )} -> 4/4 (100%) | S24: {=IFERROR( LET( base, INDIRECT(B$22), follow, INDIRECT(B23), eligible, SUM(MAP(base, follow, LAMBDA(a, b, IF(AND(ISNUMBER(a), ISNUMBER(b), a<8), 1, 0)))), reached, SUM(MAP(base, follow, LAMBDA(a, b, IF(AND(ISNUMBER(a), ISNUMBER(b), a<8, b=8), 1, 0)))), IF( eligible=0, "", reached&"/"&eligible&" ("&TEXT(reached/eligible, "0%")&")" ) ), "" )} -> 2/7 (29%) | T24: CT_FAC_V4_V1 | U24: =IFERROR(__xludf.DUMMYFUNCTION("SUMPRODUCT(--REGEXMATCH(TO_TEXT(INDIRECT(T24)), ""^\s*-?\d+(\.\d+)?\s*$""))"),5.0) -> 5 | V24: =AVERAGE(INDIRECT(T24)) -> 1.8 | W24: =STDEV(INDIRECT(T24)) -> 1.3038405 | X24: =MEDIAN(INDIRECT(T24)) -> 2 | Y24: =MIN(INDIRECT(T24)) -> 0 | Z24: =MAX(INDIRECT(T24)) -> 3 | AA24: - | AB24: - | AC24: - | AD24: =IFERROR(__xludf.DUMMYFUNCTION("IFERROR( LET( base, INDIRECT(T$22), follow, INDIRECT(T23), ratios, MAP(base, follow, LAMBDA(a, b, IF(AND(ISNUMBER(a), ISNUMBER(b), a<8), (b-a)/(8-a), """"))), clean, FILTER(ratios, ISNUMBER(ratios)), TEXT(MEDIAN(clean), ""0%"")&"" ["&"""&TEXT(QUARTILE(clean, 1), ""0%"")&""; ""&TEXT(QUARTILE(clean, 3), ""0%"")&""]"" ), """" )"),"40% [25%; 50%]") -> 40% [25%; 50%] | AE24: =IFERROR(__xludf.DUMMYFUNCTION("IFERROR( LET( delta, FILTER(INDIRECT(T24), ISNUMBER(INDIRECT(T24))), TEXT(MEDIAN(delta), ""0"")&"" [""&TEXT(QUARTILE(delta, 1), ""0"")&""; ""&TEXT(QUARTILE(delta, 3), ""0"")&""]"" ), """" )"),"2 [1; 3]") -> 2 [1; 3] | AF24: =IFERROR(__xludf.DUMMYFUNCTION("IFERROR( LET( delta, FILTER(INDIRECT(T24), ISNUMBER(INDIRECT(T24))), n, COUNT(delta), IF( n<2, TEXT(AVERAGE(delta), ""0.0""), TEXT(AVERAGE(delta), ""0.0"")&"" ± ""&TEXT(STDEV.S(delta), ""0.0"") ) ), """" )"),"1.8 ± 1.3") -> 1.8 ± 1.3 | AG24: =IFERROR(__xludf.DUMMYFUNCTION("IFERROR( LET( r, INDIRECT(T24), improved, COUNTIF(r, "">0""), total, COUNT(FILTER(r, ISNUMBER(r))), improved&""/""&total&"" (""&TEXT(improved/total, ""0%"")&"")"" ), """" )"),"4/5 (80%)") -> 4/5 (80%) | AH24: =IFERROR(__xludf.DUMMYFUNCTION("IFERROR( LET( r, INDIRECT(T24), stable, COUNTIF(r, 0), total, COUNT(FILTER(r, ISNUMBER(r))), stable&""/""&total&"" (""&TEXT(stable/total, ""0%"")&"")"" ), """" )"),"1/5 (20%)") -> 1/5 (20%) | AI24: =IFERROR(__xludf.DUMMYFUNCTION("IFERROR( LET( r, INDIRECT(T24), worsened, COUNTIF(r, ""<0""), total, COUNT(FILTER(r, ISNUMBER(r))), worsened&""/""&total&"" (""&TEXT(worsened/total, ""0%"")&"")"" ), """" )"),"0/5 (0%)") -> 0/5 (0%) | AJ24: {=IFERROR( LET( base, INDIRECT(B$22), follow, INDIRECT(B23), eligible, SUM(MAP(base, follow, LAMBDA(a, b, IF(AND(ISNUMBER(a), ISNUMBER(b), a<4), 1, 0)))), crossed, SUM(MAP(base, follow, LAMBDA(a, b, IF(AND(ISNUMBER(a), ISNUMBER(b), a<4, b>=4), 1, 0)))), crossed&"/"&eligible&" ("&TEXT(crossed/eligible, "0%")&")" ), "" )} -> 4/4 (100%) | AK24: {=IFERROR( LET( base, INDIRECT(T$22), follow, INDIRECT(T23), eligible, SUM(MAP(base, follow, LAMBDA(a, b, IF(AND(ISNUMBER(a), ISNUMBER(b), a<8), 1, 0)))), reached, SUM(MAP(base, follow, LAMBDA(a, b, IF(AND(ISNUMBER(a), ISNUMBER(b), a<8, b=8), 1, 0)))), IF( eligible=0, "", reached&"/"&eligible&" ("&TEXT(reached/eligible, "0%")&")" ) ), "" )} -> 0/5 (0%) | AL24: =D24-V24 -> 1.0571429 | AM24: =IFERROR(__xludf.DUMMYFUNCTION("IFERROR( LET( x, FILTER(INDIRECT(B24), ISNUMBER(INDIRECT(B24))), y, FILTER(INDIRECT(T24), ISNUMBER(INDIRECT(T24))), pooled, VSTACK(x, y), n_test, COUNT(x), n_control, COUNT(y), n_total, n_test+n_control, rank_sum_test, SUM(MA"&"P(x, LAMBDA(v, 1+COUNTIF(pooled, ""<""&v)+(COUNTIF(pooled, v)-1)/2))), u_test, rank_sum_test-n_test*(n_test+1)/2, u_control, n_test*n_control-u_test, u_stat, MIN(u_test, u_control), tie_term, SUM(MAP(UNIQUE(pooled), LAMBDA(v, COUNTIF(poole"&"d, v)^3-COUNTIF(pooled, v)))), mean_u, n_test*n_control/2, sd_u, SQRT(n_test*n_control/12*(n_total+1-tie_term/(n_total*(n_total-1)))), z, MAX(0, ABS(u_stat-mean_u)-0.5)/sd_u, 2*(1-NORM.S.DIST(z, TRUE)) ), """" )"),0.17547644897623726) -> 0.17547645 | AN24: =IFERROR( IF( NOT(ISNUMBER(AM24)), "", IF( OR(AM24<0, AM24>1), "Invalid p-value", IF( AM24<0.001, "Approx. statistically significant difference (p < 0.001)", IF( AM24<0.01, "Approx. statistically significant difference (p < 0.01)", IF( AM24<0.05, "Approx. statistically significant difference (p < 0.05)", "Not statistically significant" ) ) ) ) ), "" ) -> Not statistically significant
A26: =IFERROR(__xludf.DUMMYFUNCTION("IFERROR( LET( maxscore, 8, threshold, 4, basens, INDIRECT(B$22), followns, INDIRECT(B$23), deltansraw, INDIRECT(B$24), basectrl, INDIRECT(T$22), followctrl, INDIRECT(T$23), deltactrlraw, INDIRECT(T$24), pval, AM24,"&" deltans, FILTER(deltansraw, ISNUMBER(deltansraw)), deltactrl, FILTER(deltactrlraw, ISNUMBER(deltactrlraw)), nns, COUNT(deltans), nctrl, COUNT(deltactrl), meandeltans, AVERAGE(deltans), meandeltactrl, AVERAGE(deltactrl), sdd"&"eltans, IF(nns<2, """", STDEV(deltans)), sddeltactrl, IF(nctrl<2, """", STDEV(deltactrl)), diffdelta, meandeltans-meandeltactrl, mediandeltans, MEDIAN(deltans), qonedeltans, QUARTILE(deltans, 1), qthreedeltans, QUARTILE(deltans, 3), "&" mediandeltactrl, MEDIAN(deltactrl), qonedeltactrl, QUARTILE(deltactrl, 1), qthreedeltactrl, QUARTILE(deltactrl, 3), headns, maxscore-MEDIAN(FILTER(basens, ISNUMBER(basens))), headctrl, maxscore-MEDIAN(FILTER(basectrl, ISNUMBER(basectr"&"l))), diffhead, headns-headctrl, impns, COUNTIF(deltans, "">0""), stabns, COUNTIF(deltans, 0), worsens, COUNTIF(deltans, ""<0""), impctrl, COUNTIF(deltactrl, "">0""), stabctrl, COUNTIF(deltactrl, 0), worsectrl, COUNTIF(deltac"&"trl, ""<0""), maxvone_ns, COUNTIF(FILTER(basens, ISNUMBER(basens)), maxscore), maxvfour_ns, COUNTIF(FILTER(followns, ISNUMBER(followns)), maxscore), validvone_ns, COUNT(FILTER(basens, ISNUMBER(basens))), validvfour_ns, COUNT(FILTER(follow"&"ns, ISNUMBER(followns))), maxvone_ctrl, COUNTIF(FILTER(basectrl, ISNUMBER(basectrl)), maxscore), maxvfour_ctrl, COUNTIF(FILTER(followctrl, ISNUMBER(followctrl)), maxscore), validvone_ctrl, COUNT(FILTER(basectrl, ISNUMBER(basectrl))), vali"&"dvfour_ctrl, COUNT(FILTER(followctrl, ISNUMBER(followctrl))), independentvone_ns, COUNTIF(FILTER(basens, ISNUMBER(basens)), "">=""&threshold), independentvfour_ns, COUNTIF(FILTER(followns, ISNUMBER(followns)), "">=""&threshold), independentv"&"one_ctrl, COUNTIF(FILTER(basectrl, ISNUMBER(basectrl)), "">=""&threshold), independentvfour_ctrl, COUNTIF(FILTER(followctrl, ISNUMBER(followctrl)), "">=""&threshold), eligibleind_ns, SUM(MAP(basens, followns, LAMBDA(a, b, IF(AND(ISNUMBER(a), ISNU"&"MBER(b), a<threshold), 1, 0)))), crossedind_ns, SUM(MAP(basens, followns, LAMBDA(a, b, IF(AND(ISNUMBER(a), ISNUMBER(b), a<threshold, b>=threshold), 1, 0)))), eligibleind_ctrl, SUM(MAP(basectrl, followctrl, LAMBDA(a, b, IF(AND(ISNUMBER(a), ISNUMBE"&"R(b), a<threshold), 1, 0)))), crossedind_ctrl, SUM(MAP(basectrl, followctrl, LAMBDA(a, b, IF(AND(ISNUMBER(a), ISNUMBER(b), a<threshold, b>=threshold), 1, 0)))), eligiblemax_ns, SUM(MAP(basens, followns, LAMBDA(a, b, IF(AND(ISNUMBER(a), ISNUMBER(b"&"), a<maxscore), 1, 0)))), reachedmax_ns, SUM(MAP(basens, followns, LAMBDA(a, b, IF(AND(ISNUMBER(a), ISNUMBER(b), a<maxscore, b=maxscore), 1, 0)))), eligiblemax_ctrl, SUM(MAP(basectrl, followctrl, LAMBDA(a, b, IF(AND(ISNUMBER(a), ISNUMBER(b), a<ma"&"xscore), 1, 0)))), reachedmax_ctrl, SUM(MAP(basectrl, followctrl, LAMBDA(a, b, IF(AND(ISNUMBER(a), ISNUMBER(b), a<maxscore, b=maxscore), 1, 0)))), ptxt, IF( NOT(ISNUMBER(pval)), ""La p-valeur Mann-Whitney approximative n'est pas dispo"&"nible."", IF( OR(pval<0, pval>1), ""La p-valeur Mann-Whitney approximative est invalide."", IF( pval<0.05, ""La différence de ΔNFAC entre les groupes est approximativement statistiquement significative (p "&"= ""&TEXT(pval, ""0.000"")&"")."", ""La différence de ΔNFAC entre les groupes n'est pas statistiquement significative selon le test de Mann-Whitney approximatif (p = ""&TEXT(pval, ""0.000"")&"")."" ) ) ), ""Analyse NFAC av"&"ec prise en compte du caractère ordinal de l'échelle :""&CHAR(10)& ""- Le NFAC est une échelle ordinale de 0 à 8 : une hausse du score indique une amélioration du niveau d'autonomie à la marche.""&CHAR(10)& ""- Le changement médian V4-V1 est de """&"&TEXT(mediandeltans, ""0"")&"" [""&TEXT(qonedeltans, ""0"")&""; ""&TEXT(qthreedeltans, ""0"")&""] dans le groupe NS, contre ""&TEXT(mediandeltactrl, ""0"")&"" [""&TEXT(qonedeltactrl, ""0"")&""; ""&TEXT(qthreedeltactrl, ""0"")&""] dans le groupe contrôle."&"""&CHAR(10)& ""- À titre descriptif, le changement moyen est de ""&TEXT(meandeltans, ""0.0"")&"" ± ""&IF(nns<2, ""-"", TEXT(sddeltans, ""0.0""))&"" dans le groupe NS et de ""&TEXT(meandeltactrl, ""0.0"")&"" ± ""&IF(nctrl<2, ""-"", TEXT(sddeltactrl, """&"0.0""))&"" dans le groupe contrôle, soit une différence NS - contrôle de ""&TEXT(diffdelta, ""0.0"")&"" niveau(x).""&CHAR(10)& ""- Les patients améliorés / stables / aggravés sont : ""&impns&""/""&stabns&""/""&worsens&"" dans le groupe NS, contre ""&i"&"mpctrl&""/""&stabctrl&""/""&worsectrl&"" dans le groupe contrôle.""&CHAR(10)& ""- À V1, le nombre de patients au score maximum NFAC 8 était de ""&maxvone_ns&""/""&validvone_ns&"" (""&TEXT(maxvone_ns/validvone_ns, ""0%"")&"") dans le groupe NS et de """&"&maxvone_ctrl&""/""&validvone_ctrl&"" (""&TEXT(maxvone_ctrl/validvone_ctrl, ""0%"")&"") dans le groupe contrôle.""&CHAR(10)& ""- À V4, le nombre de patients au score maximum NFAC 8 était de ""&maxvfour_ns&""/""&validvfour_ns&"" (""&TEXT(maxvfour_ns/va"&"lidvfour_ns, ""0%"")&"") dans le groupe NS et de ""&maxvfour_ctrl&""/""&validvfour_ctrl&"" (""&TEXT(maxvfour_ctrl/validvfour_ctrl, ""0%"")&"") dans le groupe contrôle.""&CHAR(10)& ""- La marge médiane restante à V1 était de ""&TEXT(headns, ""0.0"")&"""&" niveau(x) dans le groupe NS et de ""&TEXT(headctrl, ""0.0"")&"" niveau(x) dans le groupe contrôle, soit une différence NS - contrôle de ""&TEXT(diffhead, ""0.0"")&"" niveau(x). Cette information sert surtout à repérer un éventuel effet plafond.""&CHAR(10"&")& ""- Le nombre de patients avec NFAC ≥4 était de ""&independentvone_ns&""/""&validvone_ns&"" (""&TEXT(independentvone_ns/validvone_ns, ""0%"")&"") à V1 puis ""&independentvfour_ns&""/""&validvfour_ns&"" (""&TEXT(independentvfour_ns/validvfour_ns, """&"0%"")&"") à V4 dans le groupe NS ; dans le groupe contrôle, il était de ""&independentvone_ctrl&""/""&validvone_ctrl&"" (""&TEXT(independentvone_ctrl/validvone_ctrl, ""0%"")&"") à V1 puis ""&independentvfour_ctrl&""/""&validvfour_ctrl&"" (""&TEXT(independ"&"entvfour_ctrl/validvfour_ctrl, ""0%"")&"") à V4.""&CHAR(10)& ""- Parmi les patients qui étaient sous le seuil NFAC 4 à V1, ""&IF(eligibleind_ns=0, ""aucun patient n'était éligible dans le groupe NS"", crossedind_ns&""/""&eligibleind_ns&"" (""&TEXT(cro"&"ssedind_ns/eligibleind_ns, ""0%"")&"") ont atteint NFAC ≥4 dans le groupe NS"")&"", contre ""&IF(eligibleind_ctrl=0, ""aucun patient éligible dans le groupe contrôle"", crossedind_ctrl&""/""&eligibleind_ctrl&"" (""&TEXT(crossedind_ctrl/eligibleind_ctrl, "&"""0%"")&"") dans le groupe contrôle"")&"".""&CHAR(10)& ""- Parmi les patients qui n'étaient pas déjà à NFAC 8 à V1, ""&IF(eligiblemax_ns=0, ""aucun patient n'était éligible dans le groupe NS"", reachedmax_ns&""/""&eligiblemax_ns&"" (""&TEXT(reachedmax"&"_ns/eligiblemax_ns, ""0%"")&"") ont atteint NFAC 8 dans le groupe NS"")&"", contre ""&IF(eligiblemax_ctrl=0, ""aucun patient éligible dans le groupe contrôle"", reachedmax_ctrl&""/""&eligiblemax_ctrl&"" (""&TEXT(reachedmax_ctrl/eligiblemax_ctrl, ""0%"")&"&""") dans le groupe contrôle"")&"".""&CHAR(10)& ""- ""&ptxt&CHAR(10)& ""- Interprétation : pour le NFAC, il faut privilégier les changements de catégories, les proportions de patients améliorés, et les passages de seuils fonctionnels comme NFAC ≥4 "&"ou NFAC 8. Le changement moyen est utile comme résumé descriptif, mais il doit être interprété avec prudence car l'échelle est ordinale."" ), """" )"),"Analyse NFAC avec prise en compte du caractère ordinal de l'échelle : - Le NFAC est une échelle ordinale de 0 à 8 : une hausse du score indique une amélioration du niveau d'autonomie à la marche. - Le changement médian V4-V1 est de 3 [3; 4] dans le groupe"&" NS, contre 2 [1; 3] dans le groupe contrôle. - À titre descriptif, le changement moyen est de 2.9 ± 1.1 dans le groupe NS et de 1.8 ± 1.3 dans le groupe contrôle, soit une différence NS - contrôle de 1.1 niveau(x). - Les patients améliorés / stables / ag"&"gravés sont : 7/0/0 dans le groupe NS, contre 4/1/0 dans le groupe contrôle. - À V1, le nombre de patients au score maximum NFAC 8 était de 0/7 (0%) dans le groupe NS et de 0/5 (0%) dans le groupe contrôle. - À V4, le nombre de patients au score maximum N"&"FAC 8 était de 2/7 (29%) dans le groupe NS et de 0/5 (0%) dans le groupe contrôle. - La marge médiane restante à V1 était de 5.0 niveau(x) dans le groupe NS et de 5.0 niveau(x) dans le groupe contrôle, soit une différence NS - contrôle de 0.0 niveau(x). C"&"ette information sert surtout à repérer un éventuel effet plafond. - Le nombre de patients avec NFAC ≥4 était de 3/7 (43%) à V1 puis 7/7 (100%) à V4 dans le groupe NS ; dans le groupe contrôle, il était de 1/5 (20%) à V1 puis 4/5 (80%) à V4. - Parmi les p"&"atients qui étaient sous le seuil NFAC 4 à V1, 4/4 (100%) ont atteint NFAC ≥4 dans le groupe NS, contre 3/4 (75%) dans le groupe contrôle. - Parmi les patients qui n'étaient pas déjà à NFAC 8 à V1, 2/7 (29%) ont atteint NFAC 8 dans le groupe NS, contre 0/"&"5 (0%) dans le groupe contrôle. - La différence de ΔNFAC entre les groupes n'est pas statistiquement significative selon le test de Mann-Whitney approximatif (p = 0.175). - Interprétation : pour le NFAC, il faut privilégier les changements de catégories, "&"les proportions de patients améliorés, et les passages de seuils fonctionnels comme NFAC ≥4 ou NFAC 8. Le changement moyen est utile comme résumé descriptif, mais il doit être interprété avec prudence car l'échelle est ordinale.") -> Analyse NFAC avec prise en compte du caractère ordinal de l'échelle : - Le NFAC est une échelle ordinale de 0 à 8 : une hausse du score indique une amélioration du niveau d'autonomie à la marche. - Le changement médian V4-V1 est de 3 [3; 4] dans le groupe NS, contre 2 [1; 3] dans le groupe contrôle. - À titre descriptif, le changement moyen est de 2.9 ± 1.1 dans le groupe NS et de 1.8 ± 1.3 dans le groupe contrôle, soit une différence NS - contrôle de 1.1 niveau(x). - Les patients améliorés / stables / aggravés sont : 7/0/0 dans le groupe NS, contre 4/1/0 dans le groupe contrôle. - À V1, le nombre de patients au score maximum NFAC 8 était de 0/7 (0%) dans le groupe NS et de 0/5 (0%) dans le groupe contrôle. - À V4, le nombre de patients au score maximum NFAC 8 était de 2/7 (29%) dans le groupe NS et de 0/5 (0%) dans le groupe contrôle. - La marge médiane restante à V1 était de 5.0 niveau(x) dans le groupe NS et de 5.0 niveau(x) dans le groupe contrôle, soit une différence NS - contrôle de 0.0 niveau(x). Cette information sert surtout à repérer un éventuel effet plafond. - Le nombre de patients avec NFAC ≥4 était de 3/7 (43%) à V1 puis 7/7 (100%) à V4 dans le groupe NS ; dans le groupe contrôle, il était de 1/5 (20%) à V1 puis 4/5 (80%) à V4. - Parmi les patients qui étaient sous le seuil NFAC 4 à V1, 4/4 (100%) ont atteint NFAC ≥4 dans le groupe NS, contre 3/4 (75%) dans le groupe contrôle. - Parmi les patients qui n'étaient pas déjà à NFAC 8 à V1, 2/7 (29%) ont atteint NFAC 8 dans le groupe NS, contre 0/5 (0%) dans le groupe contrôle. - La différence de ΔNFAC entre les groupes n'est pas statistiquement significative selon le test de Mann-Whitney approximatif (p = 0.175). - Interprétation : pour le NFAC, il faut privilégier les changements de catégories, les proportions de patients améliorés, et les passages de seuils fonctionnels comme NFAC ≥4 ou NFAC 8. Le changement moyen est utile comme résumé descriptif, mais il doit être interprété avec prudence car l'échelle est ordinale.
A28: MAS | B28: NS | L28: CONTROL | V28: NS versus CONTROL
D29: MAS burden score | N29: MAS burden score | V29: MAS burden
A30: Visit | B30: Named range | C30: N | D30: Mean ± SD | E30: Median [Q1-Q3] | F30: Min | G30: Max | H30: ΔV1 mean ± SD | I30: ΔV1 Median [Q1-Q3] | J30: % improved | K30: % worsened | L30: Named range | M30: N | N30: Mean ± SD | O30: Median [Q1-Q3] | P30: Min | Q30: Max | R30: ΔV1 mean ± SD | S30: ΔV1 Median [Q1-Q3] | T30: % improved | U30: % worsened | V30: Δ | W30: p-value | X30: Significance
A31: V1 | B31: NS_MAS_V1 | C31: =IFERROR(__xludf.DUMMYFUNCTION("SUMPRODUCT(--REGEXMATCH(TO_TEXT(INDIRECT(B31)), ""^\s*-?\d+(\.\d+)?\s*$""))"),7.0) -> 7 | D31: =TEXT(AVERAGE(INDIRECT(B31)), "0.0")&" ± "&TEXT(_xlfn.STDEV.S(INDIRECT(B31)), "0.0") -> 2.9 ± 1.6 | E31: =TEXT(MEDIAN(INDIRECT(B31)), "0")&" ["&TEXT(QUARTILE(INDIRECT(B31), 1), "0")&"; "&TEXT(QUARTILE(INDIRECT(B31), 3), "0")&"]" -> 3 [3; 4] | F31: =MIN(INDIRECT(B31)) -> 0 | G31: =MAX(INDIRECT(B31)) -> 5 | H31: - | I31: - | J31: - | K31: - | L31: CT_MAS_V1 | M31: =IFERROR(__xludf.DUMMYFUNCTION("SUMPRODUCT(--REGEXMATCH(TO_TEXT(INDIRECT(L31)), ""^\s*-?\d+(\.\d+)?\s*$""))"),5.0) -> 5 | N31: =TEXT(AVERAGE(INDIRECT(L31)), "0.0")&" ± "&TEXT(_xlfn.STDEV.S(INDIRECT(L31)), "0.0") -> 2.4 ± 3.6 | O31: =TEXT(MEDIAN(INDIRECT(L31)), "0")&" ["&TEXT(QUARTILE(INDIRECT(L31), 1), "0")&"; "&TEXT(QUARTILE(INDIRECT(L31), 3), "0")&"]" -> 0 [0; 4] | P31: =MIN(INDIRECT(L31)) -> 0 | Q31: =MAX(INDIRECT(L31)) -> 8 | R31: - | S31: - | T31: - | U31: - | V31: - | W31: - | X31: -
A32: V4 | B32: NS_MAS_V4 | C32: =IFERROR(__xludf.DUMMYFUNCTION("SUMPRODUCT(--REGEXMATCH(TO_TEXT(INDIRECT(B32)), ""^\s*-?\d+(\.\d+)?\s*$""))"),7.0) -> 7 | D32: =TEXT(AVERAGE(INDIRECT(B32)), "0.0")&" ± "&TEXT(_xlfn.STDEV.S(INDIRECT(B32)), "0.0") -> 0.9 ± 1.5 | E32: =TEXT(MEDIAN(INDIRECT(B32)), "0")&" ["&TEXT(QUARTILE(INDIRECT(B32), 1), "0")&"; "&TEXT(QUARTILE(INDIRECT(B32), 3), "0")&"]" -> 0 [0; 2] | F32: =MIN(INDIRECT(B32)) -> 0 | G32: =MAX(INDIRECT(B32)) -> 3 | H32: =IFERROR(__xludf.DUMMYFUNCTION("IFERROR( LET( delta, FILTER(INDIRECT(B35), ISNUMBER(INDIRECT(B35))), n, COUNT(delta), IF( n<2, TEXT(AVERAGE(delta), ""0.0""), TEXT(AVERAGE(delta), ""0.0"")&"" ± ""&TEXT(STDEV.S(delta), ""0.0"") ) ), """" )"),"-2.0 ± 1.5") -> -2.0 ± 1.5 | I32: =IFERROR(__xludf.DUMMYFUNCTION("IFERROR( LET( delta, SORT(FILTER(INDIRECT(B35), ISNUMBER(INDIRECT(B35))), 1, TRUE), n, COUNT(delta), med_obs, INDEX(delta, ROUNDUP(n/2, 0)), quart1, INDEX(delta, MAX(1, ROUNDUP(0.25*n, 0))), quart3, INDEX(delta, MAX(1, ROUNDUP(0.75*n"&", 0))), TEXT(med_obs, ""0"")&"" [""&TEXT(quart1, ""0"")&""; ""&TEXT(quart3, ""0"")&""]"" ), """" )"),"-2 [-3; 0]") -> -2 [-3; 0] | J32: =IFERROR(__xludf.DUMMYFUNCTION("IFERROR( LET( r, INDIRECT(B35), worsened, COUNTIF(r, ""<0""), total, COUNT(FILTER(r, ISNUMBER(r))), worsened&""/""&total&"" (""&TEXT(worsened/total, ""0%"")&"")"" ), """" )"),"5/7 (71%)") -> 5/7 (71%) | K32: =IFERROR(__xludf.DUMMYFUNCTION("IFERROR( LET( r, INDIRECT(B35), improved, COUNTIF(r, "">0""), total, COUNT(FILTER(r, ISNUMBER(r))), improved&""/""&total&"" (""&TEXT(improved/total, ""0%"")&"")"" ), """" )"),"0/7 (0%)") -> 0/7 (0%) | L32: CT_MAS_V4 | M32: =IFERROR(__xludf.DUMMYFUNCTION("SUMPRODUCT(--REGEXMATCH(TO_TEXT(INDIRECT(L32)), ""^\s*-?\d+(\.\d+)?\s*$""))"),5.0) -> 5 | N32: =TEXT(AVERAGE(INDIRECT(L32)), "0.0")&" ± "&TEXT(_xlfn.STDEV.S(INDIRECT(L32)), "0.0") -> 1.4 ± 1.9 | O32: =TEXT(MEDIAN(INDIRECT(L32)), "0")&" ["&TEXT(QUARTILE(INDIRECT(L32), 1), "0")&"; "&TEXT(QUARTILE(INDIRECT(L32), 3), "0")&"]" -> 0 [0; 3] | P32: =MIN(INDIRECT(L32)) -> 0 | Q32: =MAX(INDIRECT(L32)) -> 4 | R32: =IFERROR(__xludf.DUMMYFUNCTION("IFERROR( LET( delta, FILTER(INDIRECT(AB35), ISNUMBER(INDIRECT(AB35))), n, COUNT(delta), IF( n<2, TEXT(AVERAGE(delta), ""0.0""), TEXT(AVERAGE(delta), ""0.0"")&"" ± ""&TEXT(STDEV.S(delta), ""0.0"") ) ), """" )"),"-1.0 ± 2.2") -> -1.0 ± 2.2 | S32: =IFERROR(__xludf.DUMMYFUNCTION("IFERROR( LET( delta, SORT(FILTER(INDIRECT(AB35), ISNUMBER(INDIRECT(AB35))), 1, TRUE), n, COUNT(delta), med_obs, INDEX(delta, ROUNDUP(n/2, 0)), quart1, INDEX(delta, MAX(1, ROUNDUP(0.25*n, 0))), quart3, INDEX(delta, MAX(1, ROUNDUP(0.75"&"*n, 0))), TEXT(med_obs, ""0"")&"" [""&TEXT(quart1, ""0"")&""; ""&TEXT(quart3, ""0"")&""]"" ), """" )"),"0 [0; 0]") -> 0 [0; 0] | T32: =IFERROR(__xludf.DUMMYFUNCTION("IFERROR( LET( r, INDIRECT(AB35), worsened, COUNTIF(r, ""<0""), total, COUNT(FILTER(r, ISNUMBER(r))), worsened&""/""&total&"" (""&TEXT(worsened/total, ""0%"")&"")"" ), """" )"),"1/5 (20%)") -> 1/5 (20%) | U32: =IFERROR(__xludf.DUMMYFUNCTION("IFERROR( LET( r, INDIRECT(AB35), improved, COUNTIF(r, "">0""), total, COUNT(FILTER(r, ISNUMBER(r))), improved&""/""&total&"" (""&TEXT(improved/total, ""0%"")&"")"" ), """" )"),"0/5 (0%)") -> 0/5 (0%) | V32: =IFERROR(__xludf.DUMMYFUNCTION("IFERROR( AVERAGE(FILTER(INDIRECT(B35), ISNUMBER(INDIRECT(B35)))) - AVERAGE(FILTER(INDIRECT(AB35), ISNUMBER(INDIRECT(AB35)))), """" )"),-1.0) -> -1 | W32: =IFERROR(__xludf.DUMMYFUNCTION("IFERROR( LET( x, FILTER(INDIRECT(B35), ISNUMBER(INDIRECT(B35))), y, FILTER(INDIRECT(AB35), ISNUMBER(INDIRECT(AB35))), pooled, VSTACK(x, y), n_test, COUNT(x), n_control, COUNT(y), n_total, n_test+n_control, rank_sum_test, SUM("&"MAP(x, LAMBDA(v, 1+COUNTIF(pooled, ""<""&v)+(COUNTIF(pooled, v)-1)/2))), u_test, rank_sum_test-n_test*(n_test+1)/2, u_control, n_test*n_control-u_test, u_stat, MIN(u_test, u_control), tie_term, SUM(MAP(UNIQUE(pooled), LAMBDA(v, COUNTIF(poo"&"led, v)^3-COUNTIF(pooled, v)))), mean_u, n_test*n_control/2, sd_u, SQRT(n_test*n_control/12*(n_total+1-tie_term/(n_total*(n_total-1)))), z, MAX(0, ABS(u_stat-mean_u)-0.5)/sd_u, 2*(1-NORM.S.DIST(z, TRUE)) ), """" )"),0.29635301884420695) -> 0.29635302 | X32: =IFERROR( IF( OR(NOT(ISNUMBER(V32)),NOT(ISNUMBER(W32))), "", IF( W32<0.05, IF( V32<0, "Significant greater MAS reduction in NS", IF(V32>0,"Significant greater MAS reduction in control","Significant difference, no mean direction") ), IF( V32<0, "Not significant; descriptive trend favoring NS", IF(V32>0,"Not significant; descriptive trend favoring control","Not significant; no mean difference") ) ) ), "" ) -> Not significant; descriptive trend favoring NS
A33: V2-V1 | B33: NS_MAS_V2_V1 | AB33: CT_MAS_V2_V1
A34: V3-V1 | B34: NS_MAS_V3_V1 | AB34: CT_MAS_V3_V1
A35: V4-V1 | B35: NS_MAS_V4_V1 | AB35: CT_MAS_V4_V1
A36: V5-V1 | B36: NS_MAS_V5_V1 | AB36: CT_MAS_V5_V1
A37: V1 | B37: NS_MAS0_V1 | AB37: CT_MAS0_V1
A38: V2 | B38: NS_MAS0_V2 | AB38: CT_MAS0_V2
A39: V3 | B39: NS_MAS0_V3 | AB39: CT_MAS0_V3
A40: V4 | B40: NS_MAS0_V4 | AB40: CT_MAS0_V4
A41: V5 | B41: NS_MAS0_V5 | AB41: CT_MAS0_V5
A42: V2-V1 | B42: NS_MAS0_V2_V1 | AB42: CT_MAS0_V2_V1
A43: V3-V1 | B43: NS_MAS0_V3_V1 | AB43: CT_MAS0_V3_V1
A44: V4-V1 | B44: NS_MAS0_V4_V1 | AB44: CT_MAS0_V4_V1
... A71: V5-V1 | B71: NS_MASw_V5_V1 | AB71: CT_MASw_V5_V1
A73: MRC | B73: NS | M73: CONTROL | X73: NS versus CONTROL
...

Sheet Groupe NS
A1: 0 | F1: NFAC | I1: 10MWT (m/s) | L1: 6MWT (m) | O1: TUG (s) | R1: MAS burden score | U1: MRC total score
A2: Test | B2: Sex | C2: Age at inclusion | D2: Days since stroke | E2: Stroke side | F2: V1 | G2: V4 | H2: V4 - V1 | I2: V1 | J2: V4 | K2: V4 - V1 | L2: V1 | M2: V4 | N2: V4 - V1 | O2: V1 | P2: V4 | Q2: V4 - V1 | R2: V1 | S2: V4 | T2: V4 - V1 | U2: V1 | V2: V4 | W2: V4 - V1
A3: ID/KEY | E3: V1_HEMIPARETIC_SIDE | F3: V1_NFAC | G3: V1_4_NFAC | H3: - | I3: V1_10MT_SPEED_COMPUTED | J3: V1_4_10MT_SPEED_COMPUTED | K3: - | L3: V1_6MWT_DISTANCE | M3: V1_4_6MWT_DISTANCE | O3: V1_UP-AND-GO_DURÉE | P3: V1_4_UP-AND-GO_DURÉE | Q3: - | R3: - | S3: - | T3: - | U3: - | V3: - | W3: -
A4: =IFERROR(__xludf.DUMMYFUNCTION("FILTER(Data!A:A, Data!H:H=A1)"),"01_BD") -> 01_BD | C4: {=IFERROR( LET( startTxt, XLOOKUP(A4, Data!A:A, Data!E:E, ""), endTxt, XLOOKUP(A4, Data!A:A, Data!F:F, ""), startDate, DATE(VALUE(RIGHT(startTxt,4)),VALUE(MID(startTxt,4,2)),VALUE(LEFT(startTxt,2))), endDate, DATE(VALUE(RIGHT(endTxt,4)),VALUE(MID(endTxt,4,2)),VALUE(LEFT(endTxt,2))), YEARFRAC(startDate, endDate) ), "" )} | D4: 33 | E4: =IFERROR(__xludf.DUMMYFUNCTION("LET( raw, INDEX(Data!$B$3:$CN$100, MATCH($A4, Data!$A$3:$A$100, 0), MATCH(E$3, Data!$B$1:$CN$1, 0)), txt, TO_TEXT(raw), val, IF( REGEXMATCH(txt, ""^\s*-?\d+(\.\d+)?\s*$""), VALUE(txt), """" ), IF( val=0, ""Gauche"", IF( "&" val=1, ""Droit"", ""-"" ) ) )"),"-") -> - | F4: =IFERROR(__xludf.DUMMYFUNCTION("LET( raw, INDEX(Data!$B$3:$CN$100, MATCH($A4, Data!$A$3:$A$100, 0), MATCH(F$3, Data!$B$1:$CN$1, 0)), txt, TO_TEXT(raw), IF( REGEXMATCH(txt, ""^\s*-?\d+(\.\d+)?\s*$""), VALUE(txt), ""-"" ) )"),4.0) -> 4 | G4: =IFERROR(__xludf.DUMMYFUNCTION("LET( raw, INDEX(Data!$B$3:$CN$100, MATCH($A4, Data!$A$3:$A$100, 0), MATCH(G$3, Data!$B$1:$CN$1, 0)), txt, TO_TEXT(raw), IF( REGEXMATCH(txt, ""^\s*-?\d+(\.\d+)?\s*$""), VALUE(txt), ""-"" ) )"),6.0) -> 6 | H4: =IF(AND(ISNUMBER(G4), ISNUMBER($F4)), G4-$F4, "-") -> 2 | I4: =IFERROR(__xludf.DUMMYFUNCTION("LET( raw, INDEX(Data!$B$3:$CN$100, MATCH($A4, Data!$A$3:$A$100, 0), MATCH(I$3, Data!$B$1:$CN$1, 0)), txt, TO_TEXT(raw), IF( REGEXMATCH(txt, ""^\s*-?\d+(\.\d+)?\s*$""), VALUE(txt), ""-"" ) )"),0.3846153846) -> 0.38461538 | J4: =IFERROR(__xludf.DUMMYFUNCTION("LET( raw, INDEX(Data!$B$3:$CN$100, MATCH($A4, Data!$A$3:$A$100, 0), MATCH(J$3, Data!$B$1:$CN$1, 0)), txt, TO_TEXT(raw), IF( REGEXMATCH(txt, ""^\s*-?\d+(\.\d+)?\s*$""), VALUE(txt), ""-"" ) )"),0.8333333333) -> 0.83333333 | K4: =IF(AND(ISNUMBER(J4), ISNUMBER($I4)), J4-$I4, "-") -> 0.44871795 | L4: =IFERROR(__xludf.DUMMYFUNCTION("LET( raw, INDEX(Data!$B$3:$CN$100, MATCH($A4, Data!$A$3:$A$100, 0), MATCH(L$3, Data!$B$1:$CN$1, 0)), txt, TO_TEXT(raw), IF( REGEXMATCH(txt, ""^\s*-?\d+(\.\d+)?\s*$""), VALUE(txt), ""-"" ) )"),98.0) -> 98 | M4: =IFERROR(__xludf.DUMMYFUNCTION("LET( raw, INDEX(Data!$B$3:$CN$100, MATCH($A4, Data!$A$3:$A$100, 0), MATCH(M$3, Data!$B$1:$CN$1, 0)), txt, TO_TEXT(raw), IF( REGEXMATCH(txt, ""^\s*-?\d+(\.\d+)?\s*$""), VALUE(txt), ""-"" ) )"),136.0) -> 136 | N4: =IF(AND(ISNUMBER(M4), ISNUMBER($L4)), M4-$L4, "-") -> 38 | O4: =IFERROR(__xludf.DUMMYFUNCTION("LET( raw, INDEX(Data!$B$3:$CN$100, MATCH($A4, Data!$A$3:$A$100, 0), MATCH(O$3, Data!$B$1:$CN$1, 0)), txt, TO_TEXT(raw), IF( REGEXMATCH(txt, ""^\s*-?\d+(\.\d+)?\s*$""), VALUE(txt), ""-"" ) )"),19.0) -> 19 | P4: =IFERROR(__xludf.DUMMYFUNCTION("LET( raw, INDEX(Data!$B$3:$CN$100, MATCH($A4, Data!$A$3:$A$100, 0), MATCH(P$3, Data!$B$1:$CN$1, 0)), txt, TO_TEXT(raw), IF( REGEXMATCH(txt, ""^\s*-?\d+(\.\d+)?\s*$""), VALUE(txt), ""-"" ) )"),9.0) -> 9 | Q4: =IF(AND(ISNUMBER(P4), ISNUMBER($O4)), P4-$O4, "-") -> -10 | R4: 5 | S4: 3 | T4: =S4-R4 -> -2 | U4: 26 | V4: 33 | W4: =V4-U4 -> 7
A5: =IFERROR(__xludf.DUMMYFUNCTION("""COMPUTED_VALUE"""),"02_KS") -> 02_KS | C5: {=IFERROR( LET( startTxt, XLOOKUP(A5, Data!A:A, Data!E:E, ""), endTxt, XLOOKUP(A5, Data!A:A, Data!F:F, ""), startDate, DATE(VALUE(RIGHT(startTxt,4)),VALUE(MID(startTxt,4,2)),VALUE(LEFT(startTxt,2))), endDate, DATE(VALUE(RIGHT(endTxt,4)),VALUE(MID(endTxt,4,2)),VALUE(LEFT(endTxt,2))), YEARFRAC(startDate, endDate) ), "" )} | D5: 23 | E5: =IFERROR(__xludf.DUMMYFUNCTION("LET( raw, INDEX(Data!$B$3:$CN$100, MATCH($A5, Data!$A$3:$A$100, 0), MATCH(E$3, Data!$B$1:$CN$1, 0)), txt, TO_TEXT(raw), val, IF( REGEXMATCH(txt, ""^\s*-?\d+(\.\d+)?\s*$""), VALUE(txt), """" ), IF( val=0, ""Gauche"", IF( "&" val=1, ""Droit"", ""-"" ) ) )"),"-") -> - | F5: =IFERROR(__xludf.DUMMYFUNCTION("LET( raw, INDEX(Data!$B$3:$CN$100, MATCH($A5, Data!$A$3:$A$100, 0), MATCH(F$3, Data!$B$1:$CN$1, 0)), txt, TO_TEXT(raw), IF( REGEXMATCH(txt, ""^\s*-?\d+(\.\d+)?\s*$""), VALUE(txt), ""-"" ) )"),5.0) -> 5 | G5: =IFERROR(__xludf.DUMMYFUNCTION("LET( raw, INDEX(Data!$B$3:$CN$100, MATCH($A5, Data!$A$3:$A$100, 0), MATCH(G$3, Data!$B$1:$CN$1, 0)), txt, TO_TEXT(raw), IF( REGEXMATCH(txt, ""^\s*-?\d+(\.\d+)?\s*$""), VALUE(txt), ""-"" ) )"),8.0) -> 8 | H5: =IF(AND(ISNUMBER(G5), ISNUMBER($F5)), G5-$F5, "-") -> 3 | I5: =IFERROR(__xludf.DUMMYFUNCTION("LET( raw, INDEX(Data!$B$3:$CN$100, MATCH($A5, Data!$A$3:$A$100, 0), MATCH(I$3, Data!$B$1:$CN$1, 0)), txt, TO_TEXT(raw), IF( REGEXMATCH(txt, ""^\s*-?\d+(\.\d+)?\s*$""), VALUE(txt), ""-"" ) )"),0.7633587786) -> 0.76335878 | J5: =IFERROR(__xludf.DUMMYFUNCTION("LET( raw, INDEX(Data!$B$3:$CN$100, MATCH($A5, Data!$A$3:$A$100, 0), MATCH(J$3, Data!$B$1:$CN$1, 0)), txt, TO_TEXT(raw), IF( REGEXMATCH(txt, ""^\s*-?\d+(\.\d+)?\s*$""), VALUE(txt), ""-"" ) )"),1.428571429) -> 1.4285714 | K5: =IF(AND(ISNUMBER(J5), ISNUMBER($I5)), J5-$I5, "-") -> 0.66521265 | L5: =IFERROR(__xludf.DUMMYFUNCTION("LET( raw, INDEX(Data!$B$3:$CN$100, MATCH($A5, Data!$A$3:$A$100, 0), MATCH(L$3, Data!$B$1:$CN$1, 0)), txt, TO_TEXT(raw), IF( REGEXMATCH(txt, ""^\s*-?\d+(\.\d+)?\s*$""), VALUE(txt), ""-"" ) )"),274.0) -> 274 | M5: =IFERROR(__xludf.DUMMYFUNCTION("LET( raw, INDEX(Data!$B$3:$CN$100, MATCH($A5, Data!$A$3:$A$100, 0), MATCH(M$3, Data!$B$1:$CN$1, 0)), txt, TO_TEXT(raw), IF( REGEXMATCH(txt, ""^\s*-?\d+(\.\d+)?\s*$""), VALUE(txt), ""-"" ) )"),429.0) -> 429 | N5: =IF(AND(ISNUMBER(M5), ISNUMBER($L5)), M5-$L5, "-") -> 155 | O5: =IFERROR(__xludf.DUMMYFUNCTION("LET( raw, INDEX(Data!$B$3:$CN$100, MATCH($A5, Data!$A$3:$A$100, 0), MATCH(O$3, Data!$B$1:$CN$1, 0)), txt, TO_TEXT(raw), IF( REGEXMATCH(txt, ""^\s*-?\d+(\.\d+)?\s*$""), VALUE(txt), ""-"" ) )"),13.7) -> 13.7 | P5: =IFERROR(__xludf.DUMMYFUNCTION("LET( raw, INDEX(Data!$B$3:$CN$100, MATCH($A5, Data!$A$3:$A$100, 0), MATCH(P$3, Data!$B$1:$CN$1, 0)), txt, TO_TEXT(raw), IF( REGEXMATCH(txt, ""^\s*-?\d+(\.\d+)?\s*$""), VALUE(txt), ""-"" ) )"),5.8) -> 5.8 | Q5: =IF(AND(ISNUMBER(P5), ISNUMBER($O5)), P5-$O5, "-") -> -7.9 | R5: 3 | S5: 0 | T5: =S5-R5 -> -3 | U5: 31 | V5: 43 | W5: =V5-U5 -> 12
A6: =IFERROR(__xludf.DUMMYFUNCTION("""COMPUTED_VALUE"""),"03_BZ") -> 03_BZ | C6: {=IFERROR( LET( startTxt, XLOOKUP(A6, Data!A:A, Data!E:E, ""), endTxt, XLOOKUP(A6, Data!A:A, Data!F:F, ""), startDate, DATE(VALUE(RIGHT(startTxt,4)),VALUE(MID(startTxt,4,2)),VALUE(LEFT(startTxt,2))), endDate, DATE(VALUE(RIGHT(endTxt,4)),VALUE(MID(endTxt,4,2)),VALUE(LEFT(endTxt,2))), YEARFRAC(startDate, endDate) ), "" )} | D6: 34 | E6: =IFERROR(__xludf.DUMMYFUNCTION("LET( raw, INDEX(Data!$B$3:$CN$100, MATCH($A6, Data!$A$3:$A$100, 0), MATCH(E$3, Data!$B$1:$CN$1, 0)), txt, TO_TEXT(raw), val, IF( REGEXMATCH(txt, ""^\s*-?\d+(\.\d+)?\s*$""), VALUE(txt), """" ), IF( val=0, ""Gauche"", IF( "&" val=1, ""Droit"", ""-"" ) ) )"),"-") -> - | F6: =IFERROR(__xludf.DUMMYFUNCTION("LET( raw, INDEX(Data!$B$3:$CN$100, MATCH($A6, Data!$A$3:$A$100, 0), MATCH(F$3, Data!$B$1:$CN$1, 0)), txt, TO_TEXT(raw), IF( REGEXMATCH(txt, ""^\s*-?\d+(\.\d+)?\s*$""), VALUE(txt), ""-"" ) )"),5.0) -> 5 | G6: =IFERROR(__xludf.DUMMYFUNCTION("LET( raw, INDEX(Data!$B$3:$CN$100, MATCH($A6, Data!$A$3:$A$100, 0), MATCH(G$3, Data!$B$1:$CN$1, 0)), txt, TO_TEXT(raw), IF( REGEXMATCH(txt, ""^\s*-?\d+(\.\d+)?\s*$""), VALUE(txt), ""-"" ) )"),8.0) -> 8 | H6: =IF(AND(ISNUMBER(G6), ISNUMBER($F6)), G6-$F6, "-") -> 3 | I6: =IFERROR(__xludf.DUMMYFUNCTION("LET( raw, INDEX(Data!$B$3:$CN$100, MATCH($A6, Data!$A$3:$A$100, 0), MATCH(I$3, Data!$B$1:$CN$1, 0)), txt, TO_TEXT(raw), IF( REGEXMATCH(txt, ""^\s*-?\d+(\.\d+)?\s*$""), VALUE(txt), ""-"" ) )"),0.4166666667) -> 0.41666667 | J6: =IFERROR(__xludf.DUMMYFUNCTION("LET( raw, INDEX(Data!$B$3:$CN$100, MATCH($A6, Data!$A$3:$A$100, 0), MATCH(J$3, Data!$B$1:$CN$1, 0)), txt, TO_TEXT(raw), IF( REGEXMATCH(txt, ""^\s*-?\d+(\.\d+)?\s*$""), VALUE(txt), ""-"" ) )"),0.5555555556) -> 0.55555556 | K6: =IF(AND(ISNUMBER(J6), ISNUMBER($I6)), J6-$I6, "-") -> 0.13888889 | L6: =IFERROR(__xludf.DUMMYFUNCTION("LET( raw, INDEX(Data!$B$3:$CN$100, MATCH($A6, Data!$A$3:$A$100, 0), MATCH(L$3, Data!$B$1:$CN$1, 0)), txt, TO_TEXT(raw), IF( REGEXMATCH(txt, ""^\s*-?\d+(\.\d+)?\s*$""), VALUE(txt), ""-"" ) )"),172.0) -> 172 | M6: =IFERROR(__xludf.DUMMYFUNCTION("LET( raw, INDEX(Data!$B$3:$CN$100, MATCH($A6, Data!$A$3:$A$100, 0), MATCH(M$3, Data!$B$1:$CN$1, 0)), txt, TO_TEXT(raw), IF( REGEXMATCH(txt, ""^\s*-?\d+(\.\d+)?\s*$""), VALUE(txt), ""-"" ) )"),355.0) -> 355 | N6: =IF(AND(ISNUMBER(M6), ISNUMBER($L6)), M6-$L6, "-") -> 183 | O6: =IFERROR(__xludf.DUMMYFUNCTION("LET( raw, INDEX(Data!$B$3:$CN$100, MATCH($A6, Data!$A$3:$A$100, 0), MATCH(O$3, Data!$B$1:$CN$1, 0)), txt, TO_TEXT(raw), IF( REGEXMATCH(txt, ""^\s*-?\d+(\.\d+)?\s*$""), VALUE(txt), ""-"" ) )"),16.0) -> 16 | P6: =IFERROR(__xludf.DUMMYFUNCTION("LET( raw, INDEX(Data!$B$3:$CN$100, MATCH($A6, Data!$A$3:$A$100, 0), MATCH(P$3, Data!$B$1:$CN$1, 0)), txt, TO_TEXT(raw), IF( REGEXMATCH(txt, ""^\s*-?\d+(\.\d+)?\s*$""), VALUE(txt), ""-"" ) )"),6.7) -> 6.7 | Q6: =IF(AND(ISNUMBER(P6), ISNUMBER($O6)), P6-$O6, "-") -> -9.3 | R6: 3 | S6: 0 | T6: =S6-R6 -> -3 | U6: 34 | V6: 42 | W6: =V6-U6 -> 8
A7: =IFERROR(__xludf.DUMMYFUNCTION("""COMPUTED_VALUE"""),"05_MT") -> 05_MT | C7: {=IFERROR( LET( startTxt, XLOOKUP(A7, Data!A:A, Data!E:E, ""), endTxt, XLOOKUP(A7, Data!A:A, Data!F:F, ""), startDate, DATE(VALUE(RIGHT(startTxt,4)),VALUE(MID(startTxt,4,2)),VALUE(LEFT(startTxt,2))), endDate, DATE(VALUE(RIGHT(endTxt,4)),VALUE(MID(endTxt,4,2)),VALUE(LEFT(endTxt,2))), YEARFRAC(startDate, endDate) ), "" )} | D7: 150 | E7: =IFERROR(__xludf.DUMMYFUNCTION("LET( raw, INDEX(Data!$B$3:$CN$100, MATCH($A7, Data!$A$3:$A$100, 0), MATCH(E$3, Data!$B$1:$CN$1, 0)), txt, TO_TEXT(raw), val, IF( REGEXMATCH(txt, ""^\s*-?\d+(\.\d+)?\s*$""), VALUE(txt), """" ), IF( val=0, ""Gauche"", IF( "&" val=1, ""Droit"", ""-"" ) ) )"),"-") -> - | F7: =IFERROR(__xludf.DUMMYFUNCTION("LET( raw, INDEX(Data!$B$3:$CN$100, MATCH($A7, Data!$A$3:$A$100, 0), MATCH(F$3, Data!$B$1:$CN$1, 0)), txt, TO_TEXT(raw), IF( REGEXMATCH(txt, ""^\s*-?\d+(\.\d+)?\s*$""), VALUE(txt), ""-"" ) )"),3.0) -> 3 | G7: =IFERROR(__xludf.DUMMYFUNCTION("LET( raw, INDEX(Data!$B$3:$CN$100, MATCH($A7, Data!$A$3:$A$100, 0), MATCH(G$3, Data!$B$1:$CN$1, 0)), txt, TO_TEXT(raw), IF( REGEXMATCH(txt, ""^\s*-?\d+(\.\d+)?\s*$""), VALUE(txt), ""-"" ) )"),4.0) -> 4 | H7: =IF(AND(ISNUMBER(G7), ISNUMBER($F7)), G7-$F7, "-") -> 1 | I7: =IFERROR(__xludf.DUMMYFUNCTION("LET( raw, INDEX(Data!$B$3:$CN$100, MATCH($A7, Data!$A$3:$A$100, 0), MATCH(I$3, Data!$B$1:$CN$1, 0)), txt, TO_TEXT(raw), IF( REGEXMATCH(txt, ""^\s*-?\d+(\.\d+)?\s*$""), VALUE(txt), ""-"" ) )"),0.3125) -> 0.3125 | J7: =IFERROR(__xludf.DUMMYFUNCTION("LET( raw, INDEX(Data!$B$3:$CN$100, MATCH($A7, Data!$A$3:$A$100, 0), MATCH(J$3, Data!$B$1:$CN$1, 0)), txt, TO_TEXT(raw), IF( REGEXMATCH(txt, ""^\s*-?\d+(\.\d+)?\s*$""), VALUE(txt), ""-"" ) )"),0.4807692308) -> 0.48076923 | K7: =IF(AND(ISNUMBER(J7), ISNUMBER($I7)), J7-$I7, "-") -> 0.16826923 | L7: =IFERROR(__xludf.DUMMYFUNCTION("LET( raw, INDEX(Data!$B$3:$CN$100, MATCH($A7, Data!$A$3:$A$100, 0), MATCH(L$3, Data!$B$1:$CN$1, 0)), txt, TO_TEXT(raw), IF( REGEXMATCH(txt, ""^\s*-?\d+(\.\d+)?\s*$""), VALUE(txt), ""-"" ) )"),36.0) -> 36 | M7: =IFERROR(__xludf.DUMMYFUNCTION("LET( raw, INDEX(Data!$B$3:$CN$100, MATCH($A7, Data!$A$3:$A$100, 0), MATCH(M$3, Data!$B$1:$CN$1, 0)), txt, TO_TEXT(raw), IF( REGEXMATCH(txt, ""^\s*-?\d+(\.\d+)?\s*$""), VALUE(txt), ""-"" ) )"),128.0) -> 128 | N7: =IF(AND(ISNUMBER(M7), ISNUMBER($L7)), M7-$L7, "-") -> 92 | O7: =IFERROR(__xludf.DUMMYFUNCTION("LET( raw, INDEX(Data!$B$3:$CN$100, MATCH($A7, Data!$A$3:$A$100, 0), MATCH(O$3, Data!$B$1:$CN$1, 0)), txt, TO_TEXT(raw), IF( REGEXMATCH(txt, ""^\s*-?\d+(\.\d+)?\s*$""), VALUE(txt), ""-"" ) )"),95.0) -> 95 | P7: =IFERROR(__xludf.DUMMYFUNCTION("LET( raw, INDEX(Data!$B$3:$CN$100, MATCH($A7, Data!$A$3:$A$100, 0), MATCH(P$3, Data!$B$1:$CN$1, 0)), txt, TO_TEXT(raw), IF( REGEXMATCH(txt, ""^\s*-?\d+(\.\d+)?\s*$""), VALUE(txt), ""-"" ) )"),30.1) -> 30.1 | Q7: =IF(AND(ISNUMBER(P7), ISNUMBER($O7)), P7-$O7, "-") -> -64.9 | R7: 4 | S7: 0 | T7: =S7-R7 -> -4 | U7: 16 | V7: 16 | W7: =V7-U7 -> 0
A8: =IFERROR(__xludf.DUMMYFUNCTION("""COMPUTED_VALUE"""),"06_CV") -> 06_CV | C8: {=IFERROR( LET( startTxt, XLOOKUP(A8, Data!A:A, Data!E:E, ""), endTxt, XLOOKUP(A8, Data!A:A, Data!F:F, ""), startDate, DATE(VALUE(RIGHT(startTxt,4)),VALUE(MID(startTxt,4,2)),VALUE(LEFT(startTxt,2))), endDate, DATE(VALUE(RIGHT(endTxt,4)),VALUE(MID(endTxt,4,2)),VALUE(LEFT(endTxt,2))), YEARFRAC(startDate, endDate) ), "" )} | D8: 36 | E8: =IFERROR(__xludf.DUMMYFUNCTION("LET( raw, INDEX(Data!$B$3:$CN$100, MATCH($A8, Data!$A$3:$A$100, 0), MATCH(E$3, Data!$B$1:$CN$1, 0)), txt, TO_TEXT(raw), val, IF( REGEXMATCH(txt, ""^\s*-?\d+(\.\d+)?\s*$""), VALUE(txt), """" ), IF( val=0, ""Gauche"", IF( "&" val=1, ""Droit"", ""-"" ) ) )"),"-") -> - | F8: =IFERROR(__xludf.DUMMYFUNCTION("LET( raw, INDEX(Data!$B$3:$CN$100, MATCH($A8, Data!$A$3:$A$100, 0), MATCH(F$3, Data!$B$1:$CN$1, 0)), txt, TO_TEXT(raw), IF( REGEXMATCH(txt, ""^\s*-?\d+(\.\d+)?\s*$""), VALUE(txt), ""-"" ) )"),3.0) -> 3 | G8: =IFERROR(__xludf.DUMMYFUNCTION("LET( raw, INDEX(Data!$B$3:$CN$100, MATCH($A8, Data!$A$3:$A$100, 0), MATCH(G$3, Data!$B$1:$CN$1, 0)), txt, TO_TEXT(raw), IF( REGEXMATCH(txt, ""^\s*-?\d+(\.\d+)?\s*$""), VALUE(txt), ""-"" ) )"),7.0) -> 7 | H8: =IF(AND(ISNUMBER(G8), ISNUMBER($F8)), G8-$F8, "-") -> 4 | I8: =IFERROR(__xludf.DUMMYFUNCTION("LET( raw, INDEX(Data!$B$3:$CN$100, MATCH($A8, Data!$A$3:$A$100, 0), MATCH(I$3, Data!$B$1:$CN$1, 0)), txt, TO_TEXT(raw), IF( REGEXMATCH(txt, ""^\s*-?\d+(\.\d+)?\s*$""), VALUE(txt), ""-"" ) )"),0.5555555556) -> 0.55555556 | J8: =IFERROR(__xludf.DUMMYFUNCTION("LET( raw, INDEX(Data!$B$3:$CN$100, MATCH($A8, Data!$A$3:$A$100, 0), MATCH(J$3, Data!$B$1:$CN$1, 0)), txt, TO_TEXT(raw), IF( REGEXMATCH(txt, ""^\s*-?\d+(\.\d+)?\s*$""), VALUE(txt), ""-"" ) )"),1.25) -> 1.25 | K8: =IF(AND(ISNUMBER(J8), ISNUMBER($I8)), J8-$I8, "-") -> 0.69444444 | L8: =IFERROR(__xludf.DUMMYFUNCTION("LET( raw, INDEX(Data!$B$3:$CN$100, MATCH($A8, Data!$A$3:$A$100, 0), MATCH(L$3, Data!$B$1:$CN$1, 0)), txt, TO_TEXT(raw), IF( REGEXMATCH(txt, ""^\s*-?\d+(\.\d+)?\s*$""), VALUE(txt), ""-"" ) )"),94.0) -> 94 | M8: =IFERROR(__xludf.DUMMYFUNCTION("LET( raw, INDEX(Data!$B$3:$CN$100, MATCH($A8, Data!$A$3:$A$100, 0), MATCH(M$3, Data!$B$1:$CN$1, 0)), txt, TO_TEXT(raw), IF( REGEXMATCH(txt, ""^\s*-?\d+(\.\d+)?\s*$""), VALUE(txt), ""-"" ) )"),411.0) -> 411 | N8: =IF(AND(ISNUMBER(M8), ISNUMBER($L8)), M8-$L8, "-") -> 317 | O8: =IFERROR(__xludf.DUMMYFUNCTION("LET( raw, INDEX(Data!$B$3:$CN$100, MATCH($A8, Data!$A$3:$A$100, 0), MATCH(O$3, Data!$B$1:$CN$1, 0)), txt, TO_TEXT(raw), IF( REGEXMATCH(txt, ""^\s*-?\d+(\.\d+)?\s*$""), VALUE(txt), ""-"" ) )"),39.0) -> 39 | P8: =IFERROR(__xludf.DUMMYFUNCTION("LET( raw, INDEX(Data!$B$3:$CN$100, MATCH($A8, Data!$A$3:$A$100, 0), MATCH(P$3, Data!$B$1:$CN$1, 0)), txt, TO_TEXT(raw), IF( REGEXMATCH(txt, ""^\s*-?\d+(\.\d+)?\s*$""), VALUE(txt), ""-"" ) )"),8.3) -> 8.3 | Q8: =IF(AND(ISNUMBER(P8), ISNUMBER($O8)), P8-$O8, "-") -> -30.7 | R8: 2 | S8: 0 | T8: =S8-R8 -> -2 | U8: 22 | V8: 34 | W8: =V8-U8 -> 12
